<?xml version="1.0" encoding="UTF-8"?>
<testng-results skipped="0" failed="1" ignored="0" total="1" passed="0">
  <reporter-output>
  </reporter-output>
  <suite name="Default suite" duration-ms="23988" started-at="2023-05-28T12:42:07 IST" finished-at="2023-05-28T12:42:31 IST">
    <groups>
    </groups>
    <test name="Default test" duration-ms="23988" started-at="2023-05-28T12:42:07 IST" finished-at="2023-05-28T12:42:31 IST">
      <class name="TestCases.TC10_EnterInvalidCredentials">
        <test-method status="PASS" signature="setUp()[pri:0, instance:TestCases.TC10_EnterInvalidCredentials@704d6e83]" name="setUp" is-config="true" duration-ms="243" started-at="2023-05-28T12:42:07 IST" finished-at="2023-05-28T12:42:07 IST">
          <reporter-output>
          </reporter-output>
        </test-method> <!-- setUp -->
        <test-method status="FAIL" signature="EnterInvalidCredentials()[pri:0, instance:TestCases.TC10_EnterInvalidCredentials@704d6e83]" name="EnterInvalidCredentials" duration-ms="23914" started-at="2023-05-28T12:42:07 IST" finished-at="2023-05-28T12:42:31 IST">
          <exception class="java.lang.AssertionError">
            <message>
              <![CDATA[expected [Your password is incorrect] but found [Your password is not correct]]]>
            </message>
            <full-stacktrace>
              <![CDATA[java.lang.AssertionError: expected [Your password is incorrect] but found [Your password is not correct]
at org.testng.Assert.fail(Assert.java:99)
at org.testng.Assert.failNotEquals(Assert.java:1037)
at org.testng.Assert.assertEqualsImpl(Assert.java:140)
at org.testng.Assert.assertEquals(Assert.java:122)
at org.testng.Assert.assertEquals(Assert.java:629)
at org.testng.Assert.assertEquals(Assert.java:639)
at TestCases.TC10_EnterInvalidCredentials.EnterInvalidCredentials(TC10_EnterInvalidCredentials.java:66)
at sun.reflect.NativeMethodAccessorImpl.invoke0(Native Method)
at sun.reflect.NativeMethodAccessorImpl.invoke(Unknown Source)
at sun.reflect.DelegatingMethodAccessorImpl.invoke(Unknown Source)
at java.lang.reflect.Method.invoke(Unknown Source)
at org.testng.internal.MethodInvocationHelper.invokeMethod(MethodInvocationHelper.java:133)
at org.testng.internal.TestInvoker.invokeMethod(TestInvoker.java:598)
at org.testng.internal.TestInvoker.invokeTestMethod(TestInvoker.java:173)
at org.testng.internal.MethodRunner.runInSequence(MethodRunner.java:46)
at org.testng.internal.TestInvoker$MethodInvocationAgent.invoke(TestInvoker.java:824)
at org.testng.internal.TestInvoker.invokeTestMethods(TestInvoker.java:146)
at org.testng.internal.TestMethodWorker.invokeTestMethods(TestMethodWorker.java:146)
at org.testng.internal.TestMethodWorker.run(TestMethodWorker.java:128)
at java.util.ArrayList.forEach(Unknown Source)
at org.testng.TestRunner.privateRun(TestRunner.java:794)
at org.testng.TestRunner.run(TestRunner.java:596)
at org.testng.SuiteRunner.runTest(SuiteRunner.java:377)
at org.testng.SuiteRunner.runSequentially(SuiteRunner.java:371)
at org.testng.SuiteRunner.privateRun(SuiteRunner.java:332)
at org.testng.SuiteRunner.run(SuiteRunner.java:276)
at org.testng.SuiteRunnerWorker.runSuite(SuiteRunnerWorker.java:53)
at org.testng.SuiteRunnerWorker.run(SuiteRunnerWorker.java:96)
at org.testng.TestNG.runSuitesSequentially(TestNG.java:1212)
at org.testng.TestNG.runSuitesLocally(TestNG.java:1134)
at org.testng.TestNG.runSuites(TestNG.java:1063)
at org.testng.TestNG.run(TestNG.java:1031)
at org.testng.remote.AbstractRemoteTestNG.run(AbstractRemoteTestNG.java:115)
at org.testng.remote.RemoteTestNG.initAndRun(RemoteTestNG.java:251)
at org.testng.remote.RemoteTestNG.main(RemoteTestNG.java:77)
]]>
            </full-stacktrace>
          </exception> <!-- java.lang.AssertionError -->
          <reporter-output>
          </reporter-output>
        </test-method> <!-- EnterInvalidCredentials -->
        <test-method status="FAIL" signature="getResult(org.testng.ITestResult)[pri:0, instance:TestCases.TC10_EnterInvalidCredentials@704d6e83]" name="getResult" is-config="true" duration-ms="28" started-at="2023-05-28T12:42:31 IST" finished-at="2023-05-28T12:42:31 IST">
          <params>
            <param index="0">
              <value>
                <![CDATA[[TestResult name=EnterInvalidCredentials status=FAILURE method=TC10_EnterInvalidCredentials.EnterInvalidCredentials()[pri:0, instance:TestCases.TC10_EnterInvalidCredentials@704d6e83] output={null}]]]>
              </value>
            </param>
          </params>
          <exception class="java.lang.NullPointerException">
            <full-stacktrace>
              <![CDATA[java.lang.NullPointerException
at JavaGenericUtility.TakeScreenShot.takeScreenShot(TakeScreenShot.java:16)
at ExtentReportUtility.ExtentReportBaseClass.getResult(ExtentReportBaseClass.java:54)
at sun.reflect.NativeMethodAccessorImpl.invoke0(Native Method)
at sun.reflect.NativeMethodAccessorImpl.invoke(Unknown Source)
at sun.reflect.DelegatingMethodAccessorImpl.invoke(Unknown Source)
at java.lang.reflect.Method.invoke(Unknown Source)
at org.testng.internal.MethodInvocationHelper.invokeMethod(MethodInvocationHelper.java:133)
at org.testng.internal.MethodInvocationHelper.invokeMethodConsideringTimeout(MethodInvocationHelper.java:62)
at org.testng.internal.ConfigInvoker.invokeConfigurationMethod(ConfigInvoker.java:385)
at org.testng.internal.ConfigInvoker.invokeConfigurations(ConfigInvoker.java:321)
at org.testng.internal.TestInvoker.runConfigMethods(TestInvoker.java:700)
at org.testng.internal.TestInvoker.runAfterGroupsConfigurations(TestInvoker.java:676)
at org.testng.internal.TestInvoker.invokeMethod(TestInvoker.java:660)
at org.testng.internal.TestInvoker.invokeTestMethod(TestInvoker.java:173)
at org.testng.internal.MethodRunner.runInSequence(MethodRunner.java:46)
at org.testng.internal.TestInvoker$MethodInvocationAgent.invoke(TestInvoker.java:824)
at org.testng.internal.TestInvoker.invokeTestMethods(TestInvoker.java:146)
at org.testng.internal.TestMethodWorker.invokeTestMethods(TestMethodWorker.java:146)
at org.testng.internal.TestMethodWorker.run(TestMethodWorker.java:128)
at java.util.ArrayList.forEach(Unknown Source)
at org.testng.TestRunner.privateRun(TestRunner.java:794)
at org.testng.TestRunner.run(TestRunner.java:596)
at org.testng.SuiteRunner.runTest(SuiteRunner.java:377)
at org.testng.SuiteRunner.runSequentially(SuiteRunner.java:371)
at org.testng.SuiteRunner.privateRun(SuiteRunner.java:332)
at org.testng.SuiteRunner.run(SuiteRunner.java:276)
at org.testng.SuiteRunnerWorker.runSuite(SuiteRunnerWorker.java:53)
at org.testng.SuiteRunnerWorker.run(SuiteRunnerWorker.java:96)
at org.testng.TestNG.runSuitesSequentially(TestNG.java:1212)
at org.testng.TestNG.runSuitesLocally(TestNG.java:1134)
at org.testng.TestNG.runSuites(TestNG.java:1063)
at org.testng.TestNG.run(TestNG.java:1031)
at org.testng.remote.AbstractRemoteTestNG.run(AbstractRemoteTestNG.java:115)
at org.testng.remote.RemoteTestNG.initAndRun(RemoteTestNG.java:251)
at org.testng.remote.RemoteTestNG.main(RemoteTestNG.java:77)
]]>
            </full-stacktrace>
          </exception> <!-- java.lang.NullPointerException -->
          <reporter-output>
          </reporter-output>
        </test-method> <!-- getResult -->
        <test-method status="PASS" signature="tearDown()[pri:0, instance:TestCases.TC10_EnterInvalidCredentials@704d6e83]" name="tearDown" is-config="true" duration-ms="1041" started-at="2023-05-28T12:42:31 IST" finished-at="2023-05-28T12:42:32 IST">
          <reporter-output>
          </reporter-output>
        </test-method> <!-- tearDown -->
      </class> <!-- TestCases.TC10_EnterInvalidCredentials -->
    </test> <!-- Default test -->
  </suite> <!-- Default suite -->
</testng-results>
